Workbook

Sheet IMPORT_DATA
A1: COUNTRY | B1: Qty(KGS) | C1: Units | D1: Product Name | E1: PRICE PER KGS | F1: Currency | G1: IMPORTER NAME | H1: SUPPLIER NAME | I1: MONTH | J1: PRICE FOR KGS(USD) | K1: PRICE(USD) | L1: QTY(MTS) | M1: TOTAL PRICE(USD) | N1: PRODUCT_CATEGORY | O1: PRICE FOR TONN(USD) | P1: TOTAL PRICE(USD-TONN) | Q1: Year | R1: IMPORTER NAME_FINAL | S1: SUPPLIER NAME_FINAL
A2: AUSTRALIA | B2: 18648 | C2: KGS | D2: MCCP ACECEL 102 (90M) USP | E2: 2.352 | F2: AUD | G2: SIGACHI INDUSTRIES | H2: RAVENSWOOD | I2: Jan | J2: =IF(F2="USD", E2, E2 * IFERROR(VLOOKUP(F2, EXCHANGE_RATE!A:B, 2, FALSE), "Currency not found")) -> 1.50528 | K2: =ROUNDUP(J2,2) -> 1.51 | L2: =IF(C2="MTS", B2, B2 * IFERROR(VLOOKUP(C2, 'QTY_CONVERSIONS '!A:B, 2, FALSE), "Units not found")) -> 18.648 | M2: =B2*K2 -> 28158.48 | N2: =IFERROR(VLOOKUP(D2, Product_Category!A:B, 2, FALSE), "Uncategorized") -> MCC | O2: =K2 -> 1.51 | P2: =L2*O2 -> 28.15848 | Q2: 2023 | R2: =IFERROR(VLOOKUP(G2,'Importer Name'!A:B, 2, FALSE), "") -> SIGACHI INDUSTRIES | S2: =IFERROR(VLOOKUP(H2,'Supplier name '!A:B, 2, FALSE), "") -> RAVENSWOOD
A3: BRAZIL | B3: 20000 | C3: KGS | D3: MICROCEL MCC-101 | E3: 2.6 | F3: EUR | G3: AZELIS (INDIA) | H3: ITACEL FARMO | I3: =I2 -> Jan | J3: =IF(F3="USD", E3, E3 * IFERROR(VLOOKUP(F3, EXCHANGE_RATE!A:B, 2, FALSE), "Currency not found")) -> 2.782 | K3: =ROUNDUP(J3,2) -> 2.79 | L3: =IF(C3="MTS", B3, B3 * IFERROR(VLOOKUP(C3, 'QTY_CONVERSIONS '!A:B, 2, FALSE), "Units not found")) -> 20 | M3: =B3*K3 -> 55800 | N3: =IFERROR(VLOOKUP(D3, Product_Category!A:B, 2, FALSE), "Uncategorized") -> MCC | O3: =K3 -> 2.79 | P3: =L3*O3 -> 55.8 | Q3: =Q2 -> 2023 | R3: =IFERROR(VLOOKUP(G3,'Importer Name'!A:B, 2, FALSE), "") -> AZELIS (INDIA) | S3: =IFERROR(VLOOKUP(H3,'Supplier name '!A:B, 2, FALSE), "") -> ITACEL FARMO
A4: BRAZIL | B4: 10000 | C4: KGS | D4: MICROCEL MCC-101 | E4: 2.6 | F4: EUR | G4: AZELIS (INDIA) | H4: ITACEL FARMO | I4: =I3 -> Jan | J4: =IF(F4="USD", E4, E4 * IFERROR(VLOOKUP(F4, EXCHANGE_RATE!A:B, 2, FALSE), "Currency not found")) -> 2.782 | K4: =ROUNDUP(J4,2) -> 2.79 | L4: =IF(C4="MTS", B4, B4 * IFERROR(VLOOKUP(C4, 'QTY_CONVERSIONS '!A:B, 2, FALSE), "Units not found")) -> 10 | M4: =B4*K4 -> 27900 | N4: =IFERROR(VLOOKUP(D4, Product_Category!A:B, 2, FALSE), "Uncategorized") -> MCC | O4: =K4 -> 2.79 | P4: =L4*O4 -> 27.9 | Q4: =Q3 -> 2023 | R4: =IFERROR(VLOOKUP(G4,'Importer Name'!A:B, 2, FALSE), "") -> AZELIS (INDIA) | S4: =IFERROR(VLOOKUP(H4,'Supplier name '!A:B, 2, FALSE), "") -> ITACEL FARMO
A5: BRAZIL | B5: 5000 | C5: KGS | D5: MICROCEL MCC-101 | E5: 2.6 | F5: EUR | G5: AZELIS (INDIA) | H5: ITACEL FARMO | I5: =I4 -> Jan | J5: =IF(F5="USD", E5, E5 * IFERROR(VLOOKUP(F5, EXCHANGE_RATE!A:B, 2, FALSE), "Currency not found")) -> 2.782 | K5: =ROUNDUP(J5,2) -> 2.79 | L5: =IF(C5="MTS", B5, B5 * IFERROR(VLOOKUP(C5, 'QTY_CONVERSIONS '!A:B, 2, FALSE), "Units not found")) -> 5 | M5: =B5*K5 -> 13950 | N5: =IFERROR(VLOOKUP(D5, Product_Category!A:B, 2, FALSE), "Uncategorized") -> MCC | O5: =K5 -> 2.79 | P5: =L5*O5 -> 13.95 | Q5: =Q4 -> 2023 | R5: =IFERROR(VLOOKUP(G5,'Importer Name'!A:B, 2, FALSE), "") -> AZELIS (INDIA) | S5: =IFERROR(VLOOKUP(H5,'Supplier name '!A:B, 2, FALSE), "") -> ITACEL FARMO
A6: BRAZIL | B6: 20000 | C6: KGS | D6: MICROCEL MCC-102 | E6: 2.6 | F6: EUR | G6: AZELIS (INDIA) | H6: ITACEL FARMO | I6: =I5 -> Jan | J6: =IF(F6="USD", E6, E6 * IFERROR(VLOOKUP(F6, EXCHANGE_RATE!A:B, 2, FALSE), "Currency not found")) -> 2.782 | K6: =ROUNDUP(J6,2) -> 2.79 | L6: =IF(C6="MTS", B6, B6 * IFERROR(VLOOKUP(C6, 'QTY_CONVERSIONS '!A:B, 2, FALSE), "Units not found")) -> 20 | M6: =B6*K6 -> 55800 | N6: =IFERROR(VLOOKUP(D6, Product_Category!A:B, 2, FALSE), "Uncategorized") -> MCC | O6: =K6 -> 2.79 | P6: =L6*O6 -> 55.8 | Q6: =Q5 -> 2023 | R6: =IFERROR(VLOOKUP(G6,'Importer Name'!A:B, 2, FALSE), "") -> AZELIS (INDIA) | S6: =IFERROR(VLOOKUP(H6,'Supplier name '!A:B, 2, FALSE), "") -> ITACEL FARMO
A7: BRAZIL | B7: 20000 | C7: KGS | D7: MICROCEL MCC-101 | E7: 2.6 | F7: EUR | G7: AZELIS (INDIA) | H7: ITACEL FARMO | I7: =I6 -> Jan | J7: =IF(F7="USD", E7, E7 * IFERROR(VLOOKUP(F7, EXCHANGE_RATE!A:B, 2, FALSE), "Currency not found")) -> 2.782 | K7: =ROUNDUP(J7,2) -> 2.79 | L7: =IF(C7="MTS", B7, B7 * IFERROR(VLOOKUP(C7, 'QTY_CONVERSIONS '!A:B, 2, FALSE), "Units not found")) -> 20 | M7: =B7*K7 -> 55800 | N7: =IFERROR(VLOOKUP(D7, Product_Category!A:B, 2, FALSE), "Uncategorized") -> MCC | O7: =K7 -> 2.79 | P7: =L7*O7 -> 55.8 | Q7: =Q6 -> 2023 | R7: =IFERROR(VLOOKUP(G7,'Importer Name'!A:B, 2, FALSE), "") -> AZELIS (INDIA) | S7: =IFERROR(VLOOKUP(H7,'Supplier name '!A:B, 2, FALSE), "") -> ITACEL FARMO
A8: BRAZIL | B8: 10000 | C8: KGS | D8: MICROCEL MCC-102 | E8: 2.6 | F8: EUR | G8: AZELIS (INDIA) | H8: ITACEL FARMO | I8: =I7 -> Jan | J8: =IF(F8="USD", E8, E8 * IFERROR(VLOOKUP(F8, EXCHANGE_RATE!A:B, 2, FALSE), "Currency not found")) -> 2.782 | K8: =ROUNDUP(J8,2) -> 2.79 | L8: =IF(C8="MTS", B8, B8 * IFERROR(VLOOKUP(C8, 'QTY_CONVERSIONS '!A:B, 2, FALSE), "Units not found")) -> 10 | M8: =B8*K8 -> 27900 | N8: =IFERROR(VLOOKUP(D8, Product_Category!A:B, 2, FALSE), "Uncategorized") -> MCC | O8: =K8 -> 2.79 | P8: =L8*O8 -> 27.9 | Q8: =Q7 -> 2023 | R8: =IFERROR(VLOOKUP(G8,'Importer Name'!A:B, 2, FALSE), "") -> AZELIS (INDIA) | S8: =IFERROR(VLOOKUP(H8,'Supplier name '!A:B, 2, FALSE), "") -> ITACEL FARMO
A9: BRAZIL | B9: 2900 | C9: KGS | D9: MICROCEL MCC-200 | E9: 6.6 | F9: EUR | G9: AZELIS (INDIA) | H9: ITACEL FARMO | I9: =I8 -> Jan | J9: =IF(F9="USD", E9, E9 * IFERROR(VLOOKUP(F9, EXCHANGE_RATE!A:B, 2, FALSE), "Currency not found")) -> 7.062 | K9: =ROUNDUP(J9,2) -> 7.07 | L9: =IF(C9="MTS", B9, B9 * IFERROR(VLOOKUP(C9, 'QTY_CONVERSIONS '!A:B, 2, FALSE), "Units not found")) -> 2.9 | M9: =B9*K9 -> 20503 | N9: =IFERROR(VLOOKUP(D9, Product_Category!A:B, 2, FALSE), "Uncategorized") -> MCC | O9: =K9 -> 7.07 | P9: =L9*O9 -> 20.503 | Q9: =Q8 -> 2023 | R9: =IFERROR(VLOOKUP(G9,'Importer Name'!A:B, 2, FALSE), "") -> AZELIS (INDIA) | S9: =IFERROR(VLOOKUP(H9,'Supplier name '!A:B, 2, FALSE), "") -> ITACEL FARMO
A10: CHINA | B10: 18000 | C10: KGS | D10: SODIUM CMC | E10: 3.275 | F10: USD | G10: Nipra Hydro | H10: ANQIU EAGLE | I10: =I9 -> Jan | J10: =IF(F10="USD", E10, E10 * IFERROR(VLOOKUP(F10, EXCHANGE_RATE!A:B, 2, FALSE), "Currency not found")) -> 3.275 | K10: =ROUNDUP(J10,2) -> 3.28 | L10: =IF(C10="MTS", B10, B10 * IFERROR(VLOOKUP(C10, 'QTY_CONVERSIONS '!A:B, 2, FALSE), "Units not found")) -> 18 | M10: =B10*K10 -> 59040 | N10: =IFERROR(VLOOKUP(D10, Product_Category!A:B, 2, FALSE), "Uncategorized") -> CMC | O10: =K10 -> 3.28 | P10: =L10*O10 -> 59.04 | Q10: =Q9 -> 2023 | R10: =IFERROR(VLOOKUP(G10,'Importer Name'!A:B, 2, FALSE), "") -> Nipra Hydro | S10: =IFERROR(VLOOKUP(H10,'Supplier name '!A:B, 2, FALSE), "") -> ANQIU EAGLE
A11: CHINA | B11: 18000 | C11: KGS | D11: SODIUM CMC | E11: 3.42 | F11: USD | G11: BENTEC ORGANO | H11: ANQIU EAGLE | I11: =I10 -> Jan | J11: =IF(F11="USD", E11, E11 * IFERROR(VLOOKUP(F11, EXCHANGE_RATE!A:B, 2, FALSE), "Currency not found")) -> 3.42 | K11: =ROUNDUP(J11,2) -> 3.42 | L11: =IF(C11="MTS", B11, B11 * IFERROR(VLOOKUP(C11, 'QTY_CONVERSIONS '!A:B, 2, FALSE), "Units not found")) -> 18 | M11: =B11*K11 -> 61560 | N11: =IFERROR(VLOOKUP(D11, Product_Category!A:B, 2, FALSE), "Uncategorized") -> CMC | O11: =K11 -> 3.42 | P11: =L11*O11 -> 61.56 | Q11: =Q10 -> 2023 | R11: =IFERROR(VLOOKUP(G11,'Importer Name'!A:B, 2, FALSE), "") -> BENTEC ORGANO | S11: =IFERROR(VLOOKUP(H11,'Supplier name '!A:B, 2, FALSE), "") -> ANQIU EAGLE
A12: CHINA | B12: 18000 | C12: KGS | D12: CELLULOSE ETHER-SODIUM CMC | E12: 3.04 | F12: USD | G12: PERRY TRADING | H12: ANQIU EAGLE | I12: =I11 -> Jan | J12: =IF(F12="USD", E12, E12 * IFERROR(VLOOKUP(F12, EXCHANGE_RATE!A:B, 2, FALSE), "Currency not found")) -> 3.04 | K12: =ROUNDUP(J12,2) -> 3.04 | L12: =IF(C12="MTS", B12, B12 * IFERROR(VLOOKUP(C12, 'QTY_CONVERSIONS '!A:B, 2, FALSE), "Units not found")) -> 18 | M12: =B12*K12 -> 54720 | N12: =IFERROR(VLOOKUP(D12, Product_Category!A:B, 2, FALSE), "Uncategorized") -> CMC | O12: =K12 -> 3.04 | P12: =L12*O12 -> 54.72 | Q12: =Q11 -> 2023 | R12: =IFERROR(VLOOKUP(G12,'Importer Name'!A:B, 2, FALSE), "") -> PERRY TRADING | S12: =IFERROR(VLOOKUP(H12,'Supplier name '!A:B, 2, FALSE), "") -> ANQIU EAGLE
A13: CHINA | B13: 9000 | C13: KGS | D13: SODIUM CMC | E13: 2.57 | F13: USD | G13: PRACHIN CHEMICAL | H13: ANQIU EAGLE | I13: =I12 -> Jan | J13: =IF(F13="USD", E13, E13 * IFERROR(VLOOKUP(F13, EXCHANGE_RATE!A:B, 2, FALSE), "Currency not found")) -> 2.57 | K13: =ROUNDUP(J13,2) -> 2.57 | L13: =IF(C13="MTS", B13, B13 * IFERROR(VLOOKUP(C13, 'QTY_CONVERSIONS '!A:B, 2, FALSE), "Units not found")) -> 9 | M13: =B13*K13 -> 23130 | N13: =IFERROR(VLOOKUP(D13, Product_Category!A:B, 2, FALSE), "Uncategorized") -> CMC | O13: =K13 -> 2.57 | P13: =L13*O13 -> 23.13 | Q13: =Q12 -> 2023 | R13: =IFERROR(VLOOKUP(G13,'Importer Name'!A:B, 2, FALSE), "") -> PRACHIN CHEMICAL | S13: =IFERROR(VLOOKUP(H13,'Supplier name '!A:B, 2, FALSE), "") -> ANQIU EAGLE
A14: CHINA | B14: 300 | C14: KGS | D14: SODIUM CMC | E14: 3.15 | F14: USD | G14: INGREDION INDIA | H14: CHANGSHU WEALTHY | I14: =I13 -> Jan | J14: =IF(F14="USD", E14, E14 * IFERROR(VLOOKUP(F14, EXCHANGE_RATE!A:B, 2, FALSE), "Currency not found")) -> 3.15 | K14: =ROUNDUP(J14,2) -> 3.15 | L14: =IF(C14="MTS", B14, B14 * IFERROR(VLOOKUP(C14, 'QTY_CONVERSIONS '!A:B, 2, FALSE), "Units not found")) -> 0.3 | M14: =B14*K14 -> 945 | N14: =IFERROR(VLOOKUP(D14, Product_Category!A:B, 2, FALSE), "Uncategorized") -> CMC | O14: =K14 -> 3.15 | P14: =L14*O14 -> 0.945 | Q14: =Q13 -> 2023 | R14: =IFERROR(VLOOKUP(G14,'Importer Name'!A:B, 2, FALSE), "") -> INGREDION INDIA | S14: =IFERROR(VLOOKUP(H14,'Supplier name '!A:B, 2, FALSE), "") -> CHANGSHU WEALTHY
... A23: CHINA | B23: 20 | C23: MTS | D23: SODIUM CMC | E23: 2.66 | F23: USD | G23: MERIDIAN POLYMERS | H23: CHONGQING LIHONG | I23: =I22 -> Jan | J23: =IF(F23="USD", E23, E23 * IFERROR(VLOOKUP(F23, EXCHANGE_RATE!A:B, 2, FALSE), "Currency not found")) -> 2.66 | K23: =ROUNDUP(J23,2) -> 2.66 | L23: =IF(C23="MTS", B23, B23 * IFERROR(VLOOKUP(C23, 'QTY_CONVERSIONS '!A:B, 2, FALSE), "Units not found")) -> 20 | M23: =B23*K23 -> 53.2 | N23: =IFERROR(VLOOKUP(D23, Product_Category!A:B, 2, FALSE), "Uncategorized") -> CMC | O23: =K23 -> 2.66 | P23: =L23*O23 -> 53.2 | Q23: =Q22 -> 2023 | R23: =IFERROR(VLOOKUP(G23,'Importer Name'!A:B, 2, FALSE), "") -> MERIDIAN POLYMERS | S23: =IFERROR(VLOOKUP(H23,'Supplier name '!A:B, 2, FALSE), "") -> CHONGQING LIHONG
A24: CHINA | B24: 1000 | C24: KGS | D24: SODIUM CMC USP | E24: 41.7 | F24: CNY | G24: COLGATE-PALMOLIVE | H24: CHONGQING LIHONG | I24: =I23 -> Jan | J24: =IF(F24="USD", E24, E24 * IFERROR(VLOOKUP(F24, EXCHANGE_RATE!A:B, 2, FALSE), "Currency not found")) -> 5.838 | K24: =ROUNDUP(J24,2) -> 5.84 | L24: =IF(C24="MTS", B24, B24 * IFERROR(VLOOKUP(C24, 'QTY_CONVERSIONS '!A:B, 2, FALSE), "Units not found")) -> 1 | M24: =B24*K24 -> 5840 | N24: =IFERROR(VLOOKUP(D24, Product_Category!A:B, 2, FALSE), "Uncategorized") -> CMC | O24: =K24*1000 -> 5840 | P24: =L24*O24 -> 5840 | Q24: =Q23 -> 2023 | R24: =IFERROR(VLOOKUP(G24,'Importer Name'!A:B, 2, FALSE), "") -> COLGATE-PALMOLIVE | S24: =IFERROR(VLOOKUP(H24,'Supplier name '!A:B, 2, FALSE), "") -> CHONGQING LIHONG
A25: CHINA | B25: 18000 | C25: KGS | D25: SODIUM CMC | E25: 23.6 | F25: CNY | G25: COLGATE-PALMOLIVE | H25: CHONGQING LIHONG | I25: =I24 -> Jan | J25: =IF(F25="USD", E25, E25 * IFERROR(VLOOKUP(F25, EXCHANGE_RATE!A:B, 2, FALSE), "Currency not found")) -> 3.304 | K25: =ROUNDUP(J25,2) -> 3.31 | L25: =IF(C25="MTS", B25, B25 * IFERROR(VLOOKUP(C25, 'QTY_CONVERSIONS '!A:B, 2, FALSE), "Units not found")) -> 18 | M25: =B25*K25 -> 59580 | N25: =IFERROR(VLOOKUP(D25, Product_Category!A:B, 2, FALSE), "Uncategorized") -> CMC | O25: =K25 -> 3.31 | P25: =L25*O25 -> 59.58 | Q25: =Q24 -> 2023 | R25: =IFERROR(VLOOKUP(G25,'Importer Name'!A:B, 2, FALSE), "") -> COLGATE-PALMOLIVE | S25: =IFERROR(VLOOKUP(H25,'Supplier name '!A:B, 2, FALSE), "") -> CHONGQING LIHONG
A26: CHINA | B26: 18000 | C26: KGS | D26: SODIUM CMC | E26: 28 | F26: CNY | G26: COLGATE-PALMOLIVE | H26: CHONGQING LIHONG | I26: =I25 -> Jan | J26: =IF(F26="USD", E26, E26 * IFERROR(VLOOKUP(F26, EXCHANGE_RATE!A:B, 2, FALSE), "Currency not found")) -> 3.92 | K26: =ROUNDUP(J26,2) -> 3.92 | L26: =IF(C26="MTS", B26, B26 * IFERROR(VLOOKUP(C26, 'QTY_CONVERSIONS '!A:B, 2, FALSE), "Units not found")) -> 18 | M26: =B26*K26 -> 70560 | N26: =IFERROR(VLOOKUP(D26, Product_Category!A:B, 2, FALSE), "Uncategorized") -> CMC | O26: =K26 -> 3.92 | P26: =L26*O26 -> 70.56 | Q26: =Q25 -> 2023 | R26: =IFERROR(VLOOKUP(G26,'Importer Name'!A:B, 2, FALSE), "") -> COLGATE-PALMOLIVE | S26: =IFERROR(VLOOKUP(H26,'Supplier name '!A:B, 2, FALSE), "") -> CHONGQING LIHONG
A27: CHINA | B27: 20000 | C27: KGS | D27: SODIUM CMC | E27: 2.63 | F27: USD | G27: DHARIYAL POLYMERS | H27: CHONGQING LIHONG | I27: =I26 -> Jan | J27: =IF(F27="USD", E27, E27 * IFERROR(VLOOKUP(F27, EXCHANGE_RATE!A:B, 2, FALSE), "Currency not found")) -> 2.63 | K27: =ROUNDUP(J27,2) -> 2.63 | L27: =IF(C27="MTS", B27, B27 * IFERROR(VLOOKUP(C27, 'QTY_CONVERSIONS '!A:B, 2, FALSE), "Units not found")) -> 20 | M27: =B27*K27 -> 52600 | N27: =IFERROR(VLOOKUP(D27, Product_Category!A:B, 2, FALSE), "Uncategorized") -> CMC | O27: =K27 -> 2.63 | P27: =L27*O27 -> 52.6 | Q27: =Q26 -> 2023 | R27: =IFERROR(VLOOKUP(G27,'Importer Name'!A:B, 2, FALSE), "") -> DHARIYAL POLYMERS | S27: =IFERROR(VLOOKUP(H27,'Supplier name '!A:B, 2, FALSE), "") -> CHONGQING LIHONG
A28: CHINA | B28: 20000 | C28: KGS | D28: SODIUM CMC | E28: 2.63 | F28: USD | G28: DHARIYAL POLYMERS | H28: CHONGQING LIHONG | I28: =I27 -> Jan | J28: =IF(F28="USD", E28, E28 * IFERROR(VLOOKUP(F28, EXCHANGE_RATE!A:B, 2, FALSE), "Currency not found")) -> 2.63 | K28: =ROUNDUP(J28,2) -> 2.63 | L28: =IF(C28="MTS", B28, B28 * IFERROR(VLOOKUP(C28, 'QTY_CONVERSIONS '!A:B, 2, FALSE), "Units not found")) -> 20 | M28: =B28*K28 -> 52600 | N28: =IFERROR(VLOOKUP(D28, Product_Category!A:B, 2, FALSE), "Uncategorized") -> CMC | O28: =K28 -> 2.63 | P28: =L28*O28 -> 52.6 | Q28: =Q27 -> 2023 | R28: =IFERROR(VLOOKUP(G28,'Importer Name'!A:B, 2, FALSE), "") -> DHARIYAL POLYMERS | S28: =IFERROR(VLOOKUP(H28,'Supplier name '!A:B, 2, FALSE), "") -> CHONGQING LIHONG
A29: CHINA | B29: 18000 | C29: KGS | D29: SODIUM CMC | E29: 2.96 | F29: USD | G29: KAKKAT DRUGS | H29: JIANGSU GUOTAI | I29: =I28 -> Jan | J29: =IF(F29="USD", E29, E29 * IFERROR(VLOOKUP(F29, EXCHANGE_RATE!A:B, 2, FALSE), "Currency not found")) -> 2.96 | K29: =ROUNDUP(J29,2) -> 2.96 | L29: =IF(C29="MTS", B29, B29 * IFERROR(VLOOKUP(C29, 'QTY_CONVERSIONS '!A:B, 2, FALSE), "Units not found")) -> 18 | M29: =B29*K29 -> 53280 | N29: =IFERROR(VLOOKUP(D29, Product_Category!A:B, 2, FALSE), "Uncategorized") -> CMC | O29: =K29 -> 2.96 | P29: =L29*O29 -> 53.28 | Q29: =Q28 -> 2023 | R29: =IFERROR(VLOOKUP(G29,'Importer Name'!A:B, 2, FALSE), "") -> KAKKAT DRUGS | S29: =IFERROR(VLOOKUP(H29,'Supplier name '!A:B, 2, FALSE), "") -> JIANGSU GUOTAI
A30: CHINA | B30: 1000 | C30: KGS | D30: SODIUM CMC | E30: 3.8 | F30: USD | G30: BABA ENTERPRISES | H30: JIANGSU WEIKEM | I30: =I29 -> Jan | J30: =IF(F30="USD", E30, E30 * IFERROR(VLOOKUP(F30, EXCHANGE_RATE!A:B, 2, FALSE), "Currency not found")) -> 3.8 | K30: =ROUNDUP(J30,2) -> 3.8 | L30: =IF(C30="MTS", B30, B30 * IFERROR(VLOOKUP(C30, 'QTY_CONVERSIONS '!A:B, 2, FALSE), "Units not found")) -> 1 | M30: =B30*K30 -> 3800 | N30: =IFERROR(VLOOKUP(D30, Product_Category!A:B, 2, FALSE), "Uncategorized") -> CMC | O30: =K30 -> 3.8 | P30: =L30*O30 -> 3.8 | Q30: =Q29 -> 2023 | R30: =IFERROR(VLOOKUP(G30,'Importer Name'!A:B, 2, FALSE), "") -> BABA ENTERPRISES | S30: =IFERROR(VLOOKUP(H30,'Supplier name '!A:B, 2, FALSE), "") -> JIANGSU WEIKEM
A31: CHINA | B31: 1000 | C31: KGS | D31: SODIUM CMC | E31: 3.8 | F31: USD | G31: BABA ENTERPRISES | H31: JIANGSU WEIKEM | I31: =I30 -> Jan | J31: =IF(F31="USD", E31, E31 * IFERROR(VLOOKUP(F31, EXCHANGE_RATE!A:B, 2, FALSE), "Currency not found")) -> 3.8 | K31: =ROUNDUP(J31,2) -> 3.8 | L31: =IF(C31="MTS", B31, B31 * IFERROR(VLOOKUP(C31, 'QTY_CONVERSIONS '!A:B, 2, FALSE), "Units not found")) -> 1 | M31: =B31*K31 -> 3800 | N31: =IFERROR(VLOOKUP(D31, Product_Category!A:B, 2, FALSE), "Uncategorized") -> CMC | O31: =K31 -> 3.8 | P31: =L31*O31 -> 3.8 | Q31: =Q30 -> 2023 | R31: =IFERROR(VLOOKUP(G31,'Importer Name'!A:B, 2, FALSE), "") -> BABA ENTERPRISES | S31: =IFERROR(VLOOKUP(H31,'Supplier name '!A:B, 2, FALSE), "") -> JIANGSU WEIKEM
A32: CHINA | B32: 15000 | C32: KGS | D32: SODIUM CMC | E32: 2.2366 | F32: USD | G32: PHARCOS SPECIAL | H32: JINING FORTUNE | I32: =I31 -> Jan | J32: =IF(F32="USD", E32, E32 * IFERROR(VLOOKUP(F32, EXCHANGE_RATE!A:B, 2, FALSE), "Currency not found")) -> 2.2366 | K32: =ROUNDUP(J32,2) -> 2.24 | L32: =IF(C32="MTS", B32, B32 * IFERROR(VLOOKUP(C32, 'QTY_CONVERSIONS '!A:B, 2, FALSE), "Units not found")) -> 15 | M32: =B32*K32 -> 33600 | N32: =IFERROR(VLOOKUP(D32, Product_Category!A:B, 2, FALSE), "Uncategorized") -> CMC | O32: =K32 -> 2.24 | P32: =L32*O32 -> 33.6 | Q32: =Q31 -> 2023 | R32: =IFERROR(VLOOKUP(G32,'Importer Name'!A:B, 2, FALSE), "") -> PHARCOS SPECIAL | S32: =IFERROR(VLOOKUP(H32,'Supplier name '!A:B, 2, FALSE), "") -> JINING FORTUNE
A33: CHINA | B33: 1500 | C33: KGS | D33: SODIUM CMC | E33: 2.56 | F33: USD | G33: SANGUINE GENETICS | H33: KERAY CHEM | I33: =I32 -> Jan | J33: =IF(F33="USD", E33, E33 * IFERROR(VLOOKUP(F33, EXCHANGE_RATE!A:B, 2, FALSE), "Currency not found")) -> 2.56 | K33: =ROUNDUP(J33,2) -> 2.56 | L33: =IF(C33="MTS", B33, B33 * IFERROR(VLOOKUP(C33, 'QTY_CONVERSIONS '!A:B, 2, FALSE), "Units not found")) -> 1.5 | M33: =B33*K33 -> 3840 | N33: =IFERROR(VLOOKUP(D33, Product_Category!A:B, 2, FALSE), "Uncategorized") -> CMC | O33: =K33 -> 2.56 | P33: =L33*O33 -> 3.84 | Q33: =Q32 -> 2023 | R33: =IFERROR(VLOOKUP(G33,'Importer Name'!A:B, 2, FALSE), "") -> SANGUINE GENETICS | S33: =IFERROR(VLOOKUP(H33,'Supplier name '!A:B, 2, FALSE), "") -> KERAY CHEM
A34: CHINA | B34: 23000 | C34: KGS | D34: CMC | E34: 1.97 | F34: USD | G34: PAPYRUS PAPER | H34: M/S. JOIN GOAL | I34: =I33 -> Jan | J34: =IF(F34="USD", E34, E34 * IFERROR(VLOOKUP(F34, EXCHANGE_RATE!A:B, 2, FALSE), "Currency not found")) -> 1.97 | K34: =ROUNDUP(J34,2) -> 1.97 | L34: =IF(C34="MTS", B34, B34 * IFERROR(VLOOKUP(C34, 'QTY_CONVERSIONS '!A:B, 2, FALSE), "Units not found")) -> 23 | M34: =B34*K34 -> 45310 | N34: =IFERROR(VLOOKUP(D34, Product_Category!A:B, 2, FALSE), "Uncategorized") -> CMC | O34: =K34 -> 1.97 | P34: =L34*O34 -> 45.31 | Q34: =Q33 -> 2023 | R34: =IFERROR(VLOOKUP(G34,'Importer Name'!A:B, 2, FALSE), "") -> PAPYRUS PAPER | S34: =IFERROR(VLOOKUP(H34,'Supplier name '!A:B, 2, FALSE), "") -> M/S. JOIN GOAL
A35: CHINA | B35: 10000 | C35: KGS | D35: SODIUM CMC | E35: 4.05 | F35: USD | G35: DANISCO (INDIA) | H35: SHANGHAI SHENGUANG | I35: =I34 -> Jan | J35: =IF(F35="USD", E35, E35 * IFERROR(VLOOKUP(F35, EXCHANGE_RATE!A:B, 2, FALSE), "Currency not found")) -> 4.05 | K35: =ROUNDUP(J35,2) -> 4.05 | L35: =IF(C35="MTS", B35, B35 * IFERROR(VLOOKUP(C35, 'QTY_CONVERSIONS '!A:B, 2, FALSE), "Units not found")) -> 10 | M35: =B35*K35 -> 40500 | N35: =IFERROR(VLOOKUP(D35, Product_Category!A:B, 2, FALSE), "Uncategorized") -> CMC | O35: =K35 -> 4.05 | P35: =L35*O35 -> 40.5 | Q35: =Q34 -> 2023 | R35: =IFERROR(VLOOKUP(G35,'Importer Name'!A:B, 2, FALSE), "") -> DANISCO (INDIA) | S35: =IFERROR(VLOOKUP(H35,'Supplier name '!A:B, 2, FALSE), "") -> SHANGHAI SHENGUANG
A36: CHINA | B36: 20000 | C36: KGS | D36: SODIUM CMC | E36: 3.95 | F36: USD | G36: DANISCO (INDIA) | H36: SHANGHAI SHENGUANG | I36: =I35 -> Jan | J36: =IF(F36="USD", E36, E36 * IFERROR(VLOOKUP(F36, EXCHANGE_RATE!A:B, 2, FALSE), "Currency not found")) -> 3.95 | K36: =ROUNDUP(J36,2) -> 3.95 | L36: =IF(C36="MTS", B36, B36 * IFERROR(VLOOKUP(C36, 'QTY_CONVERSIONS '!A:B, 2, FALSE), "Units not found")) -> 20 | M36: =B36*K36 -> 79000 | N36: =IFERROR(VLOOKUP(D36, Product_Category!A:B, 2, FALSE), "Uncategorized") -> CMC | O36: =K36 -> 3.95 | P36: =L36*O36 -> 79 | Q36: =Q35 -> 2023 | R36: =IFERROR(VLOOKUP(G36,'Importer Name'!A:B, 2, FALSE), "") -> DANISCO (INDIA) | S36: =IFERROR(VLOOKUP(H36,'Supplier name '!A:B, 2, FALSE), "") -> SHANGHAI SHENGUANG
... A176: JAPAN | B176: 12000 | C176: KGS | D176: MCC CEOLUS UF-711 | E176: 10.74 | F176: USD | G176: APOTEX RESEARCH | H176: ASAHI KASEI | I176: =I175 -> Jan | J176: =IF(F176="USD", E176, E176 * IFERROR(VLOOKUP(F176, EXCHANGE_RATE!A:B, 2, FALSE), "Currency not found")) -> 10.74 | K176: =ROUNDUP(J176,2) -> 10.74 | L176: =IF(C176="MTS", B176, B176 * IFERROR(VLOOKUP(C176, 'QTY_CONVERSIONS '!A:B, 2, FALSE), "Units not found")) -> 12 | M176: =B176*K176 -> 128880 | N176: =IFERROR(VLOOKUP(D176, Product_Category!A:B, 2, FALSE), "Uncategorized") -> MCC | O176: =K176 -> 10.74 | P176: =L176*O176 -> 128.88 | Q176: =Q175 -> 2023 | R176: =IFERROR(VLOOKUP(G176,'Importer Name'!A:B, 2, FALSE), "") -> APOTEX RESEARCH | S176: =IFERROR(VLOOKUP(H176,'Supplier name '!A:B, 2, FALSE), "") -> ASAHI KASEI
A177: JAPAN | B177: 300 | C177: KGS | D177: MCC CELPHERE CP-708 | E177: 66.58 | F177: USD | G177: SIGNET EXCIPIENTS | H177: ASAHI KASEI | I177: =I176 -> Jan | J177: =IF(F177="USD", E177, E177 * IFERROR(VLOOKUP(F177, EXCHANGE_RATE!A:B, 2, FALSE), "Currency not found")) -> 66.58 | K177: =ROUNDUP(J177,2) -> 66.58 | L177: =IF(C177="MTS", B177, B177 * IFERROR(VLOOKUP(C177, 'QTY_CONVERSIONS '!A:B, 2, FALSE), "Units not found")) -> 0.3 | M177: =B177*K177 -> 19974 | N177: =IFERROR(VLOOKUP(D177, Product_Category!A:B, 2, FALSE), "Uncategorized") -> MCC | O177: =K177*1000 -> 66580 | P177: =L177*O177 -> 19974 | Q177: =Q176 -> 2023 | R177: =IFERROR(VLOOKUP(G177,'Importer Name'!A:B, 2, FALSE), "") -> SIGNET EXCIPIENTS | S177: =IFERROR(VLOOKUP(H177,'Supplier name '!A:B, 2, FALSE), "") -> ASAHI KASEI
A178: JAPAN | B178: 600 | C178: KGS | D178: MCC CEOLUS UF-702 | E178: 10.74 | F178: USD | G178: MYLAN LAB | H178: M/S. ASAHI KASEI | I178: =I177 -> Jan | J178: =IF(F178="USD", E178, E178 * IFERROR(VLOOKUP(F178, EXCHANGE_RATE!A:B, 2, FALSE), "Currency not found")) -> 10.74 | K178: =ROUNDUP(J178,2) -> 10.74 | L178: =IF(C178="MTS", B178, B178 * IFERROR(VLOOKUP(C178, 'QTY_CONVERSIONS '!A:B, 2, FALSE), "Units not found")) -> 0.6 | M178: =B178*K178 -> 6444 | N178: =IFERROR(VLOOKUP(D178, Product_Category!A:B, 2, FALSE), "Uncategorized") -> MCC | O178: =K178 -> 10.74 | P178: =L178*O178 -> 6.444 | Q178: =Q177 -> 2023 | R178: =IFERROR(VLOOKUP(G178,'Importer Name'!A:B, 2, FALSE), "") -> MYLAN LAB | S178: =IFERROR(VLOOKUP(H178,'Supplier name '!A:B, 2, FALSE), "") -> M/S. ASAHI KASEI
A179: JAPAN | B179: 300 | C179: KGS | D179: MCC CEOLUS | E179: 2382 | F179: JPY | G179: KANSAI NEROLAC | H179: YONEI & CO | I179: =I178 -> Jan | J179: =IF(F179="USD", E179, E179 * IFERROR(VLOOKUP(F179, EXCHANGE_RATE!A:B, 2, FALSE), "Currency not found")) -> 15.9594 | K179: =ROUNDUP(J179,2) -> 15.96 | L179: =IF(C179="MTS", B179, B179 * IFERROR(VLOOKUP(C179, 'QTY_CONVERSIONS '!A:B, 2, FALSE), "Units not found")) -> 0.3 | M179: =B179*K179 -> 4788 | N179: =IFERROR(VLOOKUP(D179, Product_Category!A:B, 2, FALSE), "Uncategorized") -> MCC | O179: =K179*1000 -> 15960 | P179: =L179*O179 -> 4788 | Q179: =Q178 -> 2023 | R179: =IFERROR(VLOOKUP(G179,'Importer Name'!A:B, 2, FALSE), "") -> KANSAI NEROLAC | S179: =IFERROR(VLOOKUP(H179,'Supplier name '!A:B, 2, FALSE), "") -> YONEI & CO
A180: NETHERLANDS | B180: 14280 | C180: KGS | D180: LIGAMED MF-2-V-MB- MG STEARATE | E180: 5.198 | F180: EUR | G180: AZELIS (INDIA) | H180: PETER GREVEN | I180: =I179 -> Jan | J180: =IF(F180="USD", E180, E180 * IFERROR(VLOOKUP(F180, EXCHANGE_RATE!A:B, 2, FALSE), "Currency not found")) -> 5.56186 | K180: =ROUNDUP(J180,2) -> 5.57 | L180: =IF(C180="MTS", B180, B180 * IFERROR(VLOOKUP(C180, 'QTY_CONVERSIONS '!A:B, 2, FALSE), "Units not found")) -> 14.28 | M180: =B180*K180 -> 79539.6 | N180: =IFERROR(VLOOKUP(D180, Product_Category!A:B, 2, FALSE), "Uncategorized") -> MAGNESIUM STEARATE | O180: =K180 -> 5.57 | P180: =L180*O180 -> 79.5396 | Q180: =Q179 -> 2023 | R180: =IFERROR(VLOOKUP(G180,'Importer Name'!A:B, 2, FALSE), "") -> AZELIS (INDIA) | S180: =IFERROR(VLOOKUP(H180,'Supplier name '!A:B, 2, FALSE), "") -> PETER GREVEN
A181: NETHERLANDS | B181: 11340 | C181: KGS | D181: LIGAMED MF-2-V-MB- MG STEARATE | E181: 5.412 | F181: EUR | G181: AZELIS (INDIA) | H181: PETER GREVEN | I181: =I180 -> Jan | J181: =IF(F181="USD", E181, E181 * IFERROR(VLOOKUP(F181, EXCHANGE_RATE!A:B, 2, FALSE), "Currency not found")) -> 5.79084 | K181: =ROUNDUP(J181,2) -> 5.8 | L181: =IF(C181="MTS", B181, B181 * IFERROR(VLOOKUP(C181, 'QTY_CONVERSIONS '!A:B, 2, FALSE), "Units not found")) -> 11.34 | M181: =B181*K181 -> 65772 | N181: =IFERROR(VLOOKUP(D181, Product_Category!A:B, 2, FALSE), "Uncategorized") -> MAGNESIUM STEARATE | O181: =K181 -> 5.8 | P181: =L181*O181 -> 65.772 | Q181: =Q180 -> 2023 | R181: =IFERROR(VLOOKUP(G181,'Importer Name'!A:B, 2, FALSE), "") -> AZELIS (INDIA) | S181: =IFERROR(VLOOKUP(H181,'Supplier name '!A:B, 2, FALSE), "") -> PETER GREVEN
A182: NETHERLANDS | B182: 16800 | C182: KGS | D182: LIGAMED MF-2-V-MB- MG STEARATE | E182: 5.489 | F182: EUR | G182: AZELIS (INDIA) | H182: PETER GREVEN | I182: =I181 -> Jan | J182: =IF(F182="USD", E182, E182 * IFERROR(VLOOKUP(F182, EXCHANGE_RATE!A:B, 2, FALSE), "Currency not found")) -> 5.87323 | K182: =ROUNDUP(J182,2) -> 5.88 | L182: =IF(C182="MTS", B182, B182 * IFERROR(VLOOKUP(C182, 'QTY_CONVERSIONS '!A:B, 2, FALSE), "Units not found")) -> 16.8 | M182: =B182*K182 -> 98784 | N182: =IFERROR(VLOOKUP(D182, Product_Category!A:B, 2, FALSE), "Uncategorized") -> MAGNESIUM STEARATE | O182: =K182 -> 5.88 | P182: =L182*O182 -> 98.784 | Q182: =Q181 -> 2023 | R182: =IFERROR(VLOOKUP(G182,'Importer Name'!A:B, 2, FALSE), "") -> AZELIS (INDIA) | S182: =IFERROR(VLOOKUP(H182,'Supplier name '!A:B, 2, FALSE), "") -> PETER GREVEN
A183: NETHERLANDS | B183: 2520 | C183: KGS | D183: LIGAMED MF-2-V-MB- MG STEARATE | E183: 6.014 | F183: EUR | G183: MARKSANS PHARMA | H183: PETER GREVEN | I183: =I182 -> Jan | J183: =IF(F183="USD", E183, E183 * IFERROR(VLOOKUP(F183, EXCHANGE_RATE!A:B, 2, FALSE), "Currency not found")) -> 6.43498 | K183: =ROUNDUP(J183,2) -> 6.44 | L183: =IF(C183="MTS", B183, B183 * IFERROR(VLOOKUP(C183, 'QTY_CONVERSIONS '!A:B, 2, FALSE), "Units not found")) -> 2.52 | M183: =B183*K183 -> 16228.8 | N183: =IFERROR(VLOOKUP(D183, Product_Category!A:B, 2, FALSE), "Uncategorized") -> MAGNESIUM STEARATE | O183: =K183 -> 6.44 | P183: =L183*O183 -> 16.2288 | Q183: =Q182 -> 2023 | R183: =IFERROR(VLOOKUP(G183,'Importer Name'!A:B, 2, FALSE), "") -> MARKSANS PHARMA | S183: =IFERROR(VLOOKUP(H183,'Supplier name '!A:B, 2, FALSE), "") -> PETER GREVEN
A184: NETHERLANDS | B184: 840 | C184: KGS | D184: LIGAMED MF-2-V-MB- MG STEARATE | E184: 7.847 | F184: EUR | G184: MYLAN LAB | H184: PETER GREVEN | I184: =I183 -> Jan | J184: =IF(F184="USD", E184, E184 * IFERROR(VLOOKUP(F184, EXCHANGE_RATE!A:B, 2, FALSE), "Currency not found")) -> 8.39629 | K184: =ROUNDUP(J184,2) -> 8.4 | L184: =IF(C184="MTS", B184, B184 * IFERROR(VLOOKUP(C184, 'QTY_CONVERSIONS '!A:B, 2, FALSE), "Units not found")) -> 0.84 | M184: =B184*K184 -> 7056 | N184: =IFERROR(VLOOKUP(D184, Product_Category!A:B, 2, FALSE), "Uncategorized") -> MAGNESIUM STEARATE | O184: =K184 -> 8.4 | P184: =L184*O184 -> 7.056 | Q184: =Q183 -> 2023 | R184: =IFERROR(VLOOKUP(G184,'Importer Name'!A:B, 2, FALSE), "") -> MYLAN LAB | S184: =IFERROR(VLOOKUP(H184,'Supplier name '!A:B, 2, FALSE), "") -> PETER GREVEN
A185: NETHERLANDS | B185: 4725 | C185: KGS | D185: PRIMELLOSE CCS USP-NF.PH.EUR.JP | E185: 15.44 | F185: EUR | G185: IPCA LAB | H185: DFE PHARMA | I185: =I184 -> Jan | J185: =IF(F185="USD", E185, E185 * IFERROR(VLOOKUP(F185, EXCHANGE_RATE!A:B, 2, FALSE), "Currency not found")) -> 16.5208 | K185: =ROUNDUP(J185,2) -> 16.53 | L185: =IF(C185="MTS", B185, B185 * IFERROR(VLOOKUP(C185, 'QTY_CONVERSIONS '!A:B, 2, FALSE), "Units not found")) -> 4.725 | M185: =B185*K185 -> 78104.25 | N185: =IFERROR(VLOOKUP(D185, Product_Category!A:B, 2, FALSE), "Uncategorized") -> CROSCARMELLOSE SODIUM | O185: =K185 -> 16.53 | P185: =L185*O185 -> 78.10425 | Q185: =Q184 -> 2023 | R185: =IFERROR(VLOOKUP(G185,'Importer Name'!A:B, 2, FALSE), "") -> IPCA LAB | S185: =IFERROR(VLOOKUP(H185,'Supplier name '!A:B, 2, FALSE), "") -> DFE PHARMA
A186: NETHERLANDS | B186: 8820 | C186: KGS | D186: PRIMELLOSE CCS USP-NF.PH.EUR.JP | E186: 14.2 | F186: EUR | G186: IMCD INDIA | H186: DFE PHARMA | I186: =I185 -> Jan | J186: =IF(F186="USD", E186, E186 * IFERROR(VLOOKUP(F186, EXCHANGE_RATE!A:B, 2, FALSE), "Currency not found")) -> 15.194 | K186: =ROUNDUP(J186,2) -> 15.2 | L186: =IF(C186="MTS", B186, B186 * IFERROR(VLOOKUP(C186, 'QTY_CONVERSIONS '!A:B, 2, FALSE), "Units not found")) -> 8.82 | M186: =B186*K186 -> 134064 | N186: =IFERROR(VLOOKUP(D186, Product_Category!A:B, 2, FALSE), "Uncategorized") -> CROSCARMELLOSE SODIUM | O186: =K186 -> 15.2 | P186: =L186*O186 -> 134.064 | Q186: =Q185 -> 2023 | R186: =IFERROR(VLOOKUP(G186,'Importer Name'!A:B, 2, FALSE), "") -> IMCD INDIA | S186: =IFERROR(VLOOKUP(H186,'Supplier name '!A:B, 2, FALSE), "") -> DFE PHARMA
A187: NETHERLANDS | B187: 4760 | C187: KGS | D187: PRIMELLOSE CCS USP-NF.PH.EUR.JP | E187: 14.2 | F187: EUR | G187: IMCD INDIA | H187: DFE PHARMA | I187: =I186 -> Jan | J187: =IF(F187="USD", E187, E187 * IFERROR(VLOOKUP(F187, EXCHANGE_RATE!A:B, 2, FALSE), "Currency not found")) -> 15.194 | K187: =ROUNDUP(J187,2) -> 15.2 | L187: =IF(C187="MTS", B187, B187 * IFERROR(VLOOKUP(C187, 'QTY_CONVERSIONS '!A:B, 2, FALSE), "Units not found")) -> 4.76 | M187: =B187*K187 -> 72352 | N187: =IFERROR(VLOOKUP(D187, Product_Category!A:B, 2, FALSE), "Uncategorized") -> CROSCARMELLOSE SODIUM | O187: =K187 -> 15.2 | P187: =L187*O187 -> 72.352 | Q187: =Q186 -> 2023 | R187: =IFERROR(VLOOKUP(G187,'Importer Name'!A:B, 2, FALSE), "") -> IMCD INDIA | S187: =IFERROR(VLOOKUP(H187,'Supplier name '!A:B, 2, FALSE), "") -> DFE PHARMA
...

Sheet EXPORT_DATA
A1: Country | B1: Qty(KGS) | C1: Units | D1: Product Name | E1: PRICE PER KGS | F1: Currency | G1: SOURCE COMPANY | H1: CUSTOMER NAME | I1: MONTH | J1: PRICE FOR KGS(USD) | K1: PRICE(USD) | L1: QTY(MTS) | M1: TOTAL PRICE(USD) | N1: PRODUCT_CATEGORY | O1: PRICE FOR TONN(USD) | P1: TOTAL PRICE(USD-TONN) | Q1: Year | R1: SOURCE COMPANY FINAL | S1: CUSTOMER NAME FINAL
A2: ALGERIA | B2: 4500 | C2: KGS | D2: MCC | E2: 2.55 | F2: USD | G2: JAI RADHE SALES | H2: TO THE ORDER | I2: Jan | J2: =IF(F2="USD", E2, E2 * IFERROR(VLOOKUP(F2, EXCHANGE_RATE!A:B, 2, FALSE), "Currency not found")) -> 2.55 | K2: =ROUNDUP(J2,2) -> 2.55 | L2: =IF(C2="MTS", B2, B2 * IFERROR(VLOOKUP(C2, 'QTY_CONVERSIONS '!A:B, 2, FALSE), "Units not found")) -> 4.5 | M2: =B2*K2 -> 11475 | N2: =IFERROR(VLOOKUP(D2, Product_Category!A:B, 2, FALSE), "Uncategorized") -> MCC | O2: =K2*1000 -> 2550 | P2: =L2*O2 -> 11475 | Q2: 2023 | R2: =IFERROR(VLOOKUP(G2,'SOURCE COMPANY'!A:B, 2, FALSE), "") -> JAI RADHE SALES | S2: =IFERROR(VLOOKUP(H2,'CUSTOMER NAME'!A:B, 2, FALSE), "") -> TO THE ORDER
A3: ALGERIA | B3: 13000 | C3: KGS | D3: MCC | E3: 2.45 | F3: USD | G3: JAI RADHE SALES | H3: TO THE ORDER | I3: =I2 -> Jan | J3: =IF(F3="USD", E3, E3 * IFERROR(VLOOKUP(F3, EXCHANGE_RATE!A:B, 2, FALSE), "Currency not found")) -> 2.45 | K3: =ROUNDUP(J3,2) -> 2.45 | L3: =IF(C3="MTS", B3, B3 * IFERROR(VLOOKUP(C3, 'QTY_CONVERSIONS '!A:B, 2, FALSE), "Units not found")) -> 13 | M3: =B3*K3 -> 31850 | N3: =IFERROR(VLOOKUP(D3, Product_Category!A:B, 2, FALSE), "Uncategorized") -> MCC | O3: =K3*1000 -> 2450 | P3: =L3*O3 -> 31850 | Q3: 2023 | R3: =IFERROR(VLOOKUP(G3,'SOURCE COMPANY'!A:B, 2, FALSE), "") -> JAI RADHE SALES | S3: =IFERROR(VLOOKUP(H3,'CUSTOMER NAME'!A:B, 2, FALSE), "") -> TO THE ORDER
A4: ALGERIA | B4: 12500 | C4: KGS | D4: MCC | E4: 3.95 | F4: USD | G4: JAI RADHE SALES | H4: TO THE ORDER | I4: =I3 -> Jan | J4: =IF(F4="USD", E4, E4 * IFERROR(VLOOKUP(F4, EXCHANGE_RATE!A:B, 2, FALSE), "Currency not found")) -> 3.95 | K4: =ROUNDUP(J4,2) -> 3.95 | L4: =IF(C4="MTS", B4, B4 * IFERROR(VLOOKUP(C4, 'QTY_CONVERSIONS '!A:B, 2, FALSE), "Units not found")) -> 12.5 | M4: =B4*K4 -> 49375 | N4: =IFERROR(VLOOKUP(D4, Product_Category!A:B, 2, FALSE), "Uncategorized") -> MCC | O4: =K4*1000 -> 3950 | P4: =L4*O4 -> 49375 | Q4: 2023 | R4: =IFERROR(VLOOKUP(G4,'SOURCE COMPANY'!A:B, 2, FALSE), "") -> JAI RADHE SALES | S4: =IFERROR(VLOOKUP(H4,'CUSTOMER NAME'!A:B, 2, FALSE), "") -> TO THE ORDER
A5: ALGERIA | B5: 4500 | C5: KGS | D5: MCC | E5: 2.55 | F5: USD | G5: JAI RADHE SALES | H5: TO THE ORDER | I5: =I4 -> Jan | J5: =IF(F5="USD", E5, E5 * IFERROR(VLOOKUP(F5, EXCHANGE_RATE!A:B, 2, FALSE), "Currency not found")) -> 2.55 | K5: =ROUNDUP(J5,2) -> 2.55 | L5: =IF(C5="MTS", B5, B5 * IFERROR(VLOOKUP(C5, 'QTY_CONVERSIONS '!A:B, 2, FALSE), "Units not found")) -> 4.5 | M5: =B5*K5 -> 11475 | N5: =IFERROR(VLOOKUP(D5, Product_Category!A:B, 2, FALSE), "Uncategorized") -> MCC | O5: =K5*1000 -> 2550 | P5: =L5*O5 -> 11475 | Q5: 2023 | R5: =IFERROR(VLOOKUP(G5,'SOURCE COMPANY'!A:B, 2, FALSE), "") -> JAI RADHE SALES | S5: =IFERROR(VLOOKUP(H5,'CUSTOMER NAME'!A:B, 2, FALSE), "") -> TO THE ORDER
A6: ALGERIA | B6: 13000 | C6: KGS | D6: MCC | E6: 2.45 | F6: USD | G6: JAI RADHE SALES | H6: TO THE ORDER | I6: =I5 -> Jan | J6: =IF(F6="USD", E6, E6 * IFERROR(VLOOKUP(F6, EXCHANGE_RATE!A:B, 2, FALSE), "Currency not found")) -> 2.45 | K6: =ROUNDUP(J6,2) -> 2.45 | L6: =IF(C6="MTS", B6, B6 * IFERROR(VLOOKUP(C6, 'QTY_CONVERSIONS '!A:B, 2, FALSE), "Units not found")) -> 13 | M6: =B6*K6 -> 31850 | N6: =IFERROR(VLOOKUP(D6, Product_Category!A:B, 2, FALSE), "Uncategorized") -> MCC | O6: =K6*1000 -> 2450 | P6: =L6*O6 -> 31850 | Q6: 2023 | R6: =IFERROR(VLOOKUP(G6,'SOURCE COMPANY'!A:B, 2, FALSE), "") -> JAI RADHE SALES | S6: =IFERROR(VLOOKUP(H6,'CUSTOMER NAME'!A:B, 2, FALSE), "") -> TO THE ORDER
A7: ALGERIA | B7: 12500 | C7: KGS | D7: MCC | E7: 3.95 | F7: USD | G7: JAI RADHE SALES | H7: TO THE ORDER | I7: =I6 -> Jan | J7: =IF(F7="USD", E7, E7 * IFERROR(VLOOKUP(F7, EXCHANGE_RATE!A:B, 2, FALSE), "Currency not found")) -> 3.95 | K7: =ROUNDUP(J7,2) -> 3.95 | L7: =IF(C7="MTS", B7, B7 * IFERROR(VLOOKUP(C7, 'QTY_CONVERSIONS '!A:B, 2, FALSE), "Units not found")) -> 12.5 | M7: =B7*K7 -> 49375 | N7: =IFERROR(VLOOKUP(D7, Product_Category!A:B, 2, FALSE), "Uncategorized") -> MCC | O7: =K7*1000 -> 3950 | P7: =L7*O7 -> 49375 | Q7: 2023 | R7: =IFERROR(VLOOKUP(G7,'SOURCE COMPANY'!A:B, 2, FALSE), "") -> JAI RADHE SALES | S7: =IFERROR(VLOOKUP(H7,'CUSTOMER NAME'!A:B, 2, FALSE), "") -> TO THE ORDER
A8: UAE | B8: 24000 | C8: KGS | D8: ACECEL-102 | E8: 2.04 | F8: EUR | G8: SIGACHI | H8: AEGON SHIPPING LLC | I8: October | J8: =IF(F8="USD", E8, E8 * IFERROR(VLOOKUP(F8, EXCHANGE_RATE!A:B, 2, FALSE), "Currency not found")) -> 2.1828 | K8: =ROUNDUP(J8,2) -> 2.19 | L8: =IF(C8="MTS", B8, B8 * IFERROR(VLOOKUP(C8, 'QTY_CONVERSIONS '!A:B, 2, FALSE), "Units not found")) -> 24 | M8: =B8*K8 -> 52560 | N8: =IFERROR(VLOOKUP(D8, Product_Category!A:B, 2, FALSE), "Uncategorized") -> MCC | O8: =K8*1000 -> 2190 | P8: =L8*O8 -> 52560 | Q8: 2023 | R8: =IFERROR(VLOOKUP(G8,'SOURCE COMPANY'!A:B, 2, FALSE), "") -> Sigachi Industries limited | S8: =IFERROR(VLOOKUP(H8,'CUSTOMER NAME'!A:B, 2, FALSE), "") -> AEGON SHIPPING LLC
A9: UAE | B9: 24000 | C9: KGS | D9: ACECEL-101 | E9: 1.93 | F9: EUR | G9: SIGACHI | H9: AEGON SHIPPING LLC | I9: October | J9: =IF(F9="USD", E9, E9 * IFERROR(VLOOKUP(F9, EXCHANGE_RATE!A:B, 2, FALSE), "Currency not found")) -> 2.0651 | K9: =ROUNDUP(J9,2) -> 2.07 | L9: =IF(C9="MTS", B9, B9 * IFERROR(VLOOKUP(C9, 'QTY_CONVERSIONS '!A:B, 2, FALSE), "Units not found")) -> 24 | M9: =B9*K9 -> 49680 | N9: =IFERROR(VLOOKUP(D9, Product_Category!A:B, 2, FALSE), "Uncategorized") -> MCC | O9: =K9*1000 -> 2070 | P9: =L9*O9 -> 49680 | Q9: 2023 | R9: =IFERROR(VLOOKUP(G9,'SOURCE COMPANY'!A:B, 2, FALSE), "") -> Sigachi Industries limited | S9: =IFERROR(VLOOKUP(H9,'CUSTOMER NAME'!A:B, 2, FALSE), "") -> AEGON SHIPPING LLC
A10: Nigeria | B10: 500 | C10: KGS | D10: SODIUM CMC | E10: 5.46 | F10: USD | G10: DABUR INDIA LIMITED | H10: AFRICAN CONSUMER CARE | I10: September | J10: =IF(F10="USD", E10, E10 * IFERROR(VLOOKUP(F10, EXCHANGE_RATE!A:B, 2, FALSE), "Currency not found")) -> 5.46 | K10: =ROUNDUP(J10,2) -> 5.46 | L10: =IF(C10="MTS", B10, B10 * IFERROR(VLOOKUP(C10, 'QTY_CONVERSIONS '!A:B, 2, FALSE), "Units not found")) -> 0.5 | M10: =B10*K10 -> 2730 | N10: =IFERROR(VLOOKUP(D10, Product_Category!A:B, 2, FALSE), "Uncategorized") -> CMC | O10: =K10*1000 -> 5460 | P10: =L10*O10 -> 2730 | Q10: 2023 | R10: =IFERROR(VLOOKUP(G10,'SOURCE COMPANY'!A:B, 2, FALSE), "") -> DABUR INDIA LIMITED | S10: =IFERROR(VLOOKUP(H10,'CUSTOMER NAME'!A:B, 2, FALSE), "") -> AFRICAN CONSUMER CARE
A11: CONGO | B11: 500 | C11: KGS | D11: SODIUM CMC | E11: 3.35 | F11: USD | G11: VINPA EXPORTS | H11: AFRICAN CONSUMER CARE | I11: =I10 -> September | J11: =IF(F11="USD", E11, E11 * IFERROR(VLOOKUP(F11, EXCHANGE_RATE!A:B, 2, FALSE), "Currency not found")) -> 3.35 | K11: =ROUNDUP(J11,2) -> 3.35 | L11: =IF(C11="MTS", B11, B11 * IFERROR(VLOOKUP(C11, 'QTY_CONVERSIONS '!A:B, 2, FALSE), "Units not found")) -> 0.5 | M11: =B11*K11 -> 1675 | N11: =IFERROR(VLOOKUP(D11, Product_Category!A:B, 2, FALSE), "Uncategorized") -> CMC | O11: =K11*1000 -> 3350 | P11: =L11*O11 -> 1675 | Q11: 2023 | R11: =IFERROR(VLOOKUP(G11,'SOURCE COMPANY'!A:B, 2, FALSE), "") -> VINPA EXPORTS | S11: =IFERROR(VLOOKUP(H11,'CUSTOMER NAME'!A:B, 2, FALSE), "") -> AFRICAN CONSUMER CARE
A12: Ivory Coast | B12: 400 | C12: KGS | D12: MCC BP | E12: 2.86 | F12: USD | G12: AFRICURE PHARMA | H12: AFRICURE PHARMA | I12: =I11 -> September | J12: =IF(F12="USD", E12, E12 * IFERROR(VLOOKUP(F12, EXCHANGE_RATE!A:B, 2, FALSE), "Currency not found")) -> 2.86 | K12: =ROUNDUP(J12,2) -> 2.86 | L12: =IF(C12="MTS", B12, B12 * IFERROR(VLOOKUP(C12, 'QTY_CONVERSIONS '!A:B, 2, FALSE), "Units not found")) -> 0.4 | M12: =B12*K12 -> 1144 | N12: =IFERROR(VLOOKUP(D12, Product_Category!A:B, 2, FALSE), "Uncategorized") -> MCC | O12: =K12*1000 -> 2860 | P12: =L12*O12 -> 1144 | Q12: 2023 | R12: =IFERROR(VLOOKUP(G12,'SOURCE COMPANY'!A:B, 2, FALSE), "") -> AFRICURE PHARMA | S12: =IFERROR(VLOOKUP(H12,'CUSTOMER NAME'!A:B, 2, FALSE), "") -> AFRICURE PHARMA
A13: Cameroon | B13: 250 | C13: KGS | D13: Magnesium Stearate | E13: 2.33 | F13: USD | G13: AFRICURE PHARMA | H13: AFRICURE PHARMA | I13: October | J13: =IF(F13="USD", E13, E13 * IFERROR(VLOOKUP(F13, EXCHANGE_RATE!A:B, 2, FALSE), "Currency not found")) -> 2.33 | K13: =ROUNDUP(J13,2) -> 2.33 | L13: =IF(C13="MTS", B13, B13 * IFERROR(VLOOKUP(C13, 'QTY_CONVERSIONS '!A:B, 2, FALSE), "Units not found")) -> 0.25 | M13: =B13*K13 -> 582.5 | N13: =IFERROR(VLOOKUP(D13, Product_Category!A:B, 2, FALSE), "Uncategorized") -> MAGNESIUM STEARATE | O13: =K13*1000 -> 2330 | P13: =L13*O13 -> 582.5 | Q13: 2023 | R13: =IFERROR(VLOOKUP(G13,'SOURCE COMPANY'!A:B, 2, FALSE), "") -> AFRICURE PHARMA | S13: =IFERROR(VLOOKUP(H13,'CUSTOMER NAME'!A:B, 2, FALSE), "") -> AFRICURE PHARMA
A14: DJIBOUTI | B14: 100 | C14: KGS | D14: MG STEARATE BP | E14: 2.5 | F14: USD | G14: AFRICURE PHARMA | H14: AFRICURE PHARMA | I14: =I13 -> October | J14: =IF(F14="USD", E14, E14 * IFERROR(VLOOKUP(F14, EXCHANGE_RATE!A:B, 2, FALSE), "Currency not found")) -> 2.5 | K14: =ROUNDUP(J14,2) -> 2.5 | L14: =IF(C14="MTS", B14, B14 * IFERROR(VLOOKUP(C14, 'QTY_CONVERSIONS '!A:B, 2, FALSE), "Units not found")) -> 0.1 | M14: =B14*K14 -> 250 | N14: =IFERROR(VLOOKUP(D14, Product_Category!A:B, 2, FALSE), "Uncategorized") -> MAGNESIUM STEARATE | O14: =K14*1000 -> 2500 | P14: =L14*O14 -> 250 | Q14: 2023 | R14: =IFERROR(VLOOKUP(G14,'SOURCE COMPANY'!A:B, 2, FALSE), "") -> AFRICURE PHARMA | S14: =IFERROR(VLOOKUP(H14,'CUSTOMER NAME'!A:B, 2, FALSE), "") -> AFRICURE PHARMA
A15: Cameroon | B15: 250 | C15: KGS | D15: Magnesium Stearate | E15: 2.33 | F15: USD | G15: AFRICURE PHARMA | H15: AFRICURE PHARMA | I15: September | J15: =IF(F15="USD", E15, E15 * IFERROR(VLOOKUP(F15, EXCHANGE_RATE!A:B, 2, FALSE), "Currency not found")) -> 2.33 | K15: =ROUNDUP(J15,2) -> 2.33 | L15: =IF(C15="MTS", B15, B15 * IFERROR(VLOOKUP(C15, 'QTY_CONVERSIONS '!A:B, 2, FALSE), "Units not found")) -> 0.25 | M15: =B15*K15 -> 582.5 | N15: =IFERROR(VLOOKUP(D15, Product_Category!A:B, 2, FALSE), "Uncategorized") -> MAGNESIUM STEARATE | O15: =K15*1000 -> 2330 | P15: =L15*O15 -> 582.5 | Q15: 2023 | R15: =IFERROR(VLOOKUP(G15,'SOURCE COMPANY'!A:B, 2, FALSE), "") -> AFRICURE PHARMA | S15: =IFERROR(VLOOKUP(H15,'CUSTOMER NAME'!A:B, 2, FALSE), "") -> AFRICURE PHARMA
A16: DJIBOUTI | B16: 25 | C16: KGS | D16: Magnesium Stearate BP | E16: 2.5 | F16: USD | G16: AFRICURE PHARMA | H16: AFRICURE PHARMA | I16: =I15 -> September | J16: =IF(F16="USD", E16, E16 * IFERROR(VLOOKUP(F16, EXCHANGE_RATE!A:B, 2, FALSE), "Currency not found")) -> 2.5 | K16: =ROUNDUP(J16,2) -> 2.5 | L16: =IF(C16="MTS", B16, B16 * IFERROR(VLOOKUP(C16, 'QTY_CONVERSIONS '!A:B, 2, FALSE), "Units not found")) -> 0.025 | M16: =B16*K16 -> 62.5 | N16: =IFERROR(VLOOKUP(D16, Product_Category!A:B, 2, FALSE), "Uncategorized") -> MAGNESIUM STEARATE | O16: =K16*1000 -> 2500 | P16: =L16*O16 -> 62.5 | Q16: 2023 | R16: =IFERROR(VLOOKUP(G16,'SOURCE COMPANY'!A:B, 2, FALSE), "") -> AFRICURE PHARMA | S16: =IFERROR(VLOOKUP(H16,'CUSTOMER NAME'!A:B, 2, FALSE), "") -> AFRICURE PHARMA
A17: Ivory Coast | B17: 400 | C17: KGS | D17: MCC | E17: 2.86 | F17: USD | G17: AFRICURE PHARMA | H17: AFRICURE PHARMA | I17: September | J17: =IF(F17="USD", E17, E17 * IFERROR(VLOOKUP(F17, EXCHANGE_RATE!A:B, 2, FALSE), "Currency not found")) -> 2.86 | K17: =ROUNDUP(J17,2) -> 2.86 | L17: =IF(C17="MTS", B17, B17 * IFERROR(VLOOKUP(C17, 'QTY_CONVERSIONS '!A:B, 2, FALSE), "Units not found")) -> 0.4 | M17: =B17*K17 -> 1144 | N17: =IFERROR(VLOOKUP(D17, Product_Category!A:B, 2, FALSE), "Uncategorized") -> MCC | O17: =K17*1000 -> 2860 | P17: =L17*O17 -> 1144 | Q17: 2023 | R17: =IFERROR(VLOOKUP(G17,'SOURCE COMPANY'!A:B, 2, FALSE), "") -> AFRICURE PHARMA | S17: =IFERROR(VLOOKUP(H17,'CUSTOMER NAME'!A:B, 2, FALSE), "") -> AFRICURE PHARMA
A18: Sudan | B18: 425 | C18: KGS | D18: MCC & CMC | E18: 35.643 | F18: AED | G18: GANILK PRIVATE | H18: AGEEB PARMA | I18: =I17 -> September | J18: =IF(F18="USD", E18, E18 * IFERROR(VLOOKUP(F18, EXCHANGE_RATE!A:B, 2, FALSE), "Currency not found")) -> 9.62361 | K18: =ROUNDUP(J18,2) -> 9.63 | L18: =IF(C18="MTS", B18, B18 * IFERROR(VLOOKUP(C18, 'QTY_CONVERSIONS '!A:B, 2, FALSE), "Units not found")) -> 0.425 | M18: =B18*K18 -> 4092.75 | N18: =IFERROR(VLOOKUP(D18, Product_Category!A:B, 2, FALSE), "Uncategorized") -> CMC | O18: =K18*1000 -> 9630 | P18: =L18*O18 -> 4092.75 | Q18: 2023 | R18: =IFERROR(VLOOKUP(G18,'SOURCE COMPANY'!A:B, 2, FALSE), "") -> GANILK PRIVATE | S18: =IFERROR(VLOOKUP(H18,'CUSTOMER NAME'!A:B, 2, FALSE), "") -> AGEEB PARMA
A19: Sudan | B19: 425 | C19: KGS | D19: MCC & CMC | E19: 35.643 | F19: AED | G19: GANILK PRIVATE | H19: AGEEB PARMA | I19: =I18 -> September | J19: =IF(F19="USD", E19, E19 * IFERROR(VLOOKUP(F19, EXCHANGE_RATE!A:B, 2, FALSE), "Currency not found")) -> 9.62361 | K19: =ROUNDUP(J19,2) -> 9.63 | L19: =IF(C19="MTS", B19, B19 * IFERROR(VLOOKUP(C19, 'QTY_CONVERSIONS '!A:B, 2, FALSE), "Units not found")) -> 0.425 | M19: =B19*K19 -> 4092.75 | N19: =IFERROR(VLOOKUP(D19, Product_Category!A:B, 2, FALSE), "Uncategorized") -> CMC | O19: =K19*1000 -> 9630 | P19: =L19*O19 -> 4092.75 | Q19: 2023 | R19: =IFERROR(VLOOKUP(G19,'SOURCE COMPANY'!A:B, 2, FALSE), "") -> GANILK PRIVATE | S19: =IFERROR(VLOOKUP(H19,'CUSTOMER NAME'!A:B, 2, FALSE), "") -> AGEEB PARMA
A20: UAE | B20: 1 | C20: KGS | D20: CMC | E20: 3.72 | F20: USD | G20: RATNAVEL TRADERS | H20: AL HANEEN Manufacturing | I20: November | J20: =IF(F20="USD", E20, E20 * IFERROR(VLOOKUP(F20, EXCHANGE_RATE!A:B, 2, FALSE), "Currency not found")) -> 3.72 | K20: =ROUNDUP(J20,2) -> 3.72 | L20: =IF(C20="MTS", B20, B20 * IFERROR(VLOOKUP(C20, 'QTY_CONVERSIONS '!A:B, 2, FALSE), "Units not found")) -> 0.001 | M20: =B20*K20 -> 3.72 | N20: =IFERROR(VLOOKUP(D20, Product_Category!A:B, 2, FALSE), "Uncategorized") -> CMC | O20: =K20*1000 -> 3720 | P20: =L20*O20 -> 3.72 | Q20: 2023 | R20: =IFERROR(VLOOKUP(G20,'SOURCE COMPANY'!A:B, 2, FALSE), "") -> RATNAVEL TRADERS | S20: =IFERROR(VLOOKUP(H20,'CUSTOMER NAME'!A:B, 2, FALSE), "") -> AL HANEEN Manufacturing
A21: Tunisia | B21: 2 | C21: KGS | D21: SODIUM CMC | E21: 4.94 | F21: USD | G21: SISCO LABS | H21: AL S A IND FARMA | I21: November | J21: =IF(F21="USD", E21, E21 * IFERROR(VLOOKUP(F21, EXCHANGE_RATE!A:B, 2, FALSE), "Currency not found")) -> 4.94 | K21: =ROUNDUP(J21,2) -> 4.94 | L21: =IF(C21="MTS", B21, B21 * IFERROR(VLOOKUP(C21, 'QTY_CONVERSIONS '!A:B, 2, FALSE), "Units not found")) -> 0.002 | M21: =B21*K21 -> 9.88 | N21: =IFERROR(VLOOKUP(D21, Product_Category!A:B, 2, FALSE), "Uncategorized") -> CMC | O21: =K21*1000 -> 4940 | P21: =L21*O21 -> 9.88 | Q21: 2023 | R21: =IFERROR(VLOOKUP(G21,'SOURCE COMPANY'!A:B, 2, FALSE), "") -> SISCO Research Labs | S21: =IFERROR(VLOOKUP(H21,'CUSTOMER NAME'!A:B, 2, FALSE), "") -> AL S A IND FARMA
A22: Tunisia | B22: 10 | C22: KGS | D22: SODIUM CMC | E22: 4.94 | F22: USD | G22: SISCO LABS | H22: AL S A IND FARMA | I22: November | J22: =IF(F22="USD", E22, E22 * IFERROR(VLOOKUP(F22, EXCHANGE_RATE!A:B, 2, FALSE), "Currency not found")) -> 4.94 | K22: =ROUNDUP(J22,2) -> 4.94 | L22: =IF(C22="MTS", B22, B22 * IFERROR(VLOOKUP(C22, 'QTY_CONVERSIONS '!A:B, 2, FALSE), "Units not found")) -> 0.01 | M22: =B22*K22 -> 49.4 | N22: =IFERROR(VLOOKUP(D22, Product_Category!A:B, 2, FALSE), "Uncategorized") -> CMC | O22: =K22*1000 -> 4940 | P22: =L22*O22 -> 49.4 | Q22: 2023 | R22: =IFERROR(VLOOKUP(G22,'SOURCE COMPANY'!A:B, 2, FALSE), "") -> SISCO Research Labs | S22: =IFERROR(VLOOKUP(H22,'CUSTOMER NAME'!A:B, 2, FALSE), "") -> AL S A IND FARMA
A23: Yemen | B23: 20 | C23: PCS | D23: MG STEARATE | E23: 2.4199516 | F23: USD | G23: HIGH PURITY LAB | H23: AL SHAMIL TRADING | I23: =I22 -> November | J23: =IF(F23="USD", E23, E23 * IFERROR(VLOOKUP(F23, EXCHANGE_RATE!A:B, 2, FALSE), "Currency not found")) -> 2.4199516 | K23: =ROUNDUP(J23,2) -> 2.42 | L23: =IF(C23="MTS", B23, B23 * IFERROR(VLOOKUP(C23, 'QTY_CONVERSIONS '!A:B, 2, FALSE), "Units not found")) -> 4 | M23: =B23*K23 -> 48.4 | N23: =IFERROR(VLOOKUP(D23, Product_Category!A:B, 2, FALSE), "Uncategorized") -> MAGNESIUM STEARATE | O23: =K23*1000 -> 2420 | P23: =L23*O23 -> 9680 | Q23: 2023 | R23: =IFERROR(VLOOKUP(G23,'SOURCE COMPANY'!A:B, 2, FALSE), "") -> HIGH PURITY LAB | S23: =IFERROR(VLOOKUP(H23,'CUSTOMER NAME'!A:B, 2, FALSE), "") -> AL SHAMIL TRADING
A24: Bangladesh | B24: 4000 | C24: KGS | D24: Magnesium Sterate | E24: 1.55 | F24: USD | G24: MLA INDUSTRIES | H24: AL-ARAFAH ISLAMI | I24: November | J24: =IF(F24="USD", E24, E24 * IFERROR(VLOOKUP(F24, EXCHANGE_RATE!A:B, 2, FALSE), "Currency not found")) -> 1.55 | K24: =ROUNDUP(J24,2) -> 1.55 | L24: =IF(C24="MTS", B24, B24 * IFERROR(VLOOKUP(C24, 'QTY_CONVERSIONS '!A:B, 2, FALSE), "Units not found")) -> 4 | M24: =B24*K24 -> 6200 | N24: =IFERROR(VLOOKUP(D24, Product_Category!A:B, 2, FALSE), "Uncategorized") -> MAGNESIUM STEARATE | O24: =K24*1000 -> 1550 | P24: =L24*O24 -> 6200 | Q24: 2023 | R24: =IFERROR(VLOOKUP(G24,'SOURCE COMPANY'!A:B, 2, FALSE), "") -> MLA INDUSTRIES | S24: =IFERROR(VLOOKUP(H24,'CUSTOMER NAME'!A:B, 2, FALSE), "") -> AL-ARAFAH ISLAMI
A25: Bangladesh | B25: 1000 | C25: KGS | D25: MCC NUTRACEL TM 112 USP NF PH EUR JP IP | E25: 9.6 | F25: USD | G25: DFE PHARMA | H25: ALCHEM ENTERPRISE | I25: =I24 -> November | J25: =IF(F25="USD", E25, E25 * IFERROR(VLOOKUP(F25, EXCHANGE_RATE!A:B, 2, FALSE), "Currency not found")) -> 9.6 | K25: =ROUNDUP(J25,2) -> 9.6 | L25: =IF(C25="MTS", B25, B25 * IFERROR(VLOOKUP(C25, 'QTY_CONVERSIONS '!A:B, 2, FALSE), "Units not found")) -> 1 | M25: =B25*K25 -> 9600 | N25: =IFERROR(VLOOKUP(D25, Product_Category!A:B, 2, FALSE), "Uncategorized") -> MCC | O25: =K25*1000 -> 9600 | P25: =L25*O25 -> 9600 | Q25: 2023 | R25: =IFERROR(VLOOKUP(G25,'SOURCE COMPANY'!A:B, 2, FALSE), "") -> DFE PHARMA | S25: =IFERROR(VLOOKUP(H25,'CUSTOMER NAME'!A:B, 2, FALSE), "") -> ALCHEM ENTERPRISE
A26: Bangladesh | B26: 2000 | C26: KGS | D26: MCC PHARMACEL 112 USP NF PH EUR JP IP | E26: 9 | F26: USD | G26: DFE PHARMA | H26: ALCHEM ENTERPRISE | I26: =I25 -> November | J26: =IF(F26="USD", E26, E26 * IFERROR(VLOOKUP(F26, EXCHANGE_RATE!A:B, 2, FALSE), "Currency not found")) -> 9 | K26: =ROUNDUP(J26,2) -> 9 | L26: =IF(C26="MTS", B26, B26 * IFERROR(VLOOKUP(C26, 'QTY_CONVERSIONS '!A:B, 2, FALSE), "Units not found")) -> 2 | M26: =B26*K26 -> 18000 | N26: =IFERROR(VLOOKUP(D26, Product_Category!A:B, 2, FALSE), "Uncategorized") -> MCC | O26: =K26*1000 -> 9000 | P26: =L26*O26 -> 18000 | Q26: 2023 | R26: =IFERROR(VLOOKUP(G26,'SOURCE COMPANY'!A:B, 2, FALSE), "") -> DFE PHARMA | S26: =IFERROR(VLOOKUP(H26,'CUSTOMER NAME'!A:B, 2, FALSE), "") -> ALCHEM ENTERPRISE
A27: Bangladesh | B27: 100 | C27: KGS | D27: PHARMACEL SMCC 90 MCC USP NF PH EUR JP IP | E27: 14 | F27: USD | G27: DFE PHARMA | H27: ALCHEM ENTERPRISE | I27: =I26 -> November | J27: =IF(F27="USD", E27, E27 * IFERROR(VLOOKUP(F27, EXCHANGE_RATE!A:B, 2, FALSE), "Currency not found")) -> 14 | K27: =ROUNDUP(J27,2) -> 14 | L27: =IF(C27="MTS", B27, B27 * IFERROR(VLOOKUP(C27, 'QTY_CONVERSIONS '!A:B, 2, FALSE), "Units not found")) -> 0.1 | M27: =B27*K27 -> 1400 | N27: =IFERROR(VLOOKUP(D27, Product_Category!A:B, 2, FALSE), "Uncategorized") -> MCC | O27: =K27*1000 -> 14000 | P27: =L27*O27 -> 1400 | Q27: 2023 | R27: =IFERROR(VLOOKUP(G27,'SOURCE COMPANY'!A:B, 2, FALSE), "") -> DFE PHARMA | S27: =IFERROR(VLOOKUP(H27,'CUSTOMER NAME'!A:B, 2, FALSE), "") -> ALCHEM ENTERPRISE
A28: Iraq | B28: 6 | C28: KGS | D28: Magnesium Stearate | E28: 3.5 | F28: USD | G28: SISCO LABS | H28: ALCHEMY SCIENTIFIC QUARTER | I28: October | J28: =IF(F28="USD", E28, E28 * IFERROR(VLOOKUP(F28, EXCHANGE_RATE!A:B, 2, FALSE), "Currency not found")) -> 3.5 | K28: =ROUNDUP(J28,2) -> 3.5 | L28: =IF(C28="MTS", B28, B28 * IFERROR(VLOOKUP(C28, 'QTY_CONVERSIONS '!A:B, 2, FALSE), "Units not found")) -> 0.006 | M28: =B28*K28 -> 21 | N28: =IFERROR(VLOOKUP(D28, Product_Category!A:B, 2, FALSE), "Uncategorized") -> MAGNESIUM STEARATE | O28: =K28*1000 -> 3500 | P28: =L28*O28 -> 21 | Q28: 2023 | R28: =IFERROR(VLOOKUP(G28,'SOURCE COMPANY'!A:B, 2, FALSE), "") -> SISCO Research Labs | S28: =IFERROR(VLOOKUP(H28,'CUSTOMER NAME'!A:B, 2, FALSE), "") -> ALCHEMY SCIENTIFIC QUARTER
A29: Iraq | B29: 6 | C29: KGS | D29: SSG | E29: 3.16 | F29: USD | G29: SISCO LABS | H29: ALCHEMY SCIENTIFIC QUARTER | I29: October | J29: =IF(F29="USD", E29, E29 * IFERROR(VLOOKUP(F29, EXCHANGE_RATE!A:B, 2, FALSE), "Currency not found")) -> 3.16 | K29: =ROUNDUP(J29,2) -> 3.16 | L29: =IF(C29="MTS", B29, B29 * IFERROR(VLOOKUP(C29, 'QTY_CONVERSIONS '!A:B, 2, FALSE), "Units not found")) -> 0.006 | M29: =B29*K29 -> 18.96 | N29: =IFERROR(VLOOKUP(D29, Product_Category!A:B, 2, FALSE), "Uncategorized") -> SSG | O29: =K29*1000 -> 3160 | P29: =L29*O29 -> 18.96 | Q29: 2023 | R29: =IFERROR(VLOOKUP(G29,'SOURCE COMPANY'!A:B, 2, FALSE), "") -> SISCO Research Labs | S29: =IFERROR(VLOOKUP(H29,'CUSTOMER NAME'!A:B, 2, FALSE), "") -> ALCHEMY SCIENTIFIC QUARTER
A30: Iraq | B30: 6 | C30: KGS | D30: SODIUM CMC | E30: 5.26 | F30: USD | G30: SISCO LABS | H30: ALCHEMY SCIENTIFIC QUARTER | I30: October | J30: =IF(F30="USD", E30, E30 * IFERROR(VLOOKUP(F30, EXCHANGE_RATE!A:B, 2, FALSE), "Currency not found")) -> 5.26 | K30: =ROUNDUP(J30,2) -> 5.26 | L30: =IF(C30="MTS", B30, B30 * IFERROR(VLOOKUP(C30, 'QTY_CONVERSIONS '!A:B, 2, FALSE), "Units not found")) -> 0.006 | M30: =B30*K30 -> 31.56 | N30: =IFERROR(VLOOKUP(D30, Product_Category!A:B, 2, FALSE), "Uncategorized") -> CMC | O30: =K30*1000 -> 5260 | P30: =L30*O30 -> 31.56 | Q30: 2023 | R30: =IFERROR(VLOOKUP(G30,'SOURCE COMPANY'!A:B, 2, FALSE), "") -> SISCO Research Labs | S30: =IFERROR(VLOOKUP(H30,'CUSTOMER NAME'!A:B, 2, FALSE), "") -> ALCHEMY SCIENTIFIC QUARTER
A31: Iraq | B31: 6 | C31: KGS | D31: SODIUM CMC | E31: 4.94 | F31: USD | G31: SISCO LABS | H31: ALCHEMY SCIENTIFIC QUARTER | I31: October | J31: =IF(F31="USD", E31, E31 * IFERROR(VLOOKUP(F31, EXCHANGE_RATE!A:B, 2, FALSE), "Currency not found")) -> 4.94 | K31: =ROUNDUP(J31,2) -> 4.94 | L31: =IF(C31="MTS", B31, B31 * IFERROR(VLOOKUP(C31, 'QTY_CONVERSIONS '!A:B, 2, FALSE), "Units not found")) -> 0.006 | M31: =B31*K31 -> 29.64 | N31: =IFERROR(VLOOKUP(D31, Product_Category!A:B, 2, FALSE), "Uncategorized") -> CMC | O31: =K31*1000 -> 4940 | P31: =L31*O31 -> 29.64 | Q31: 2023 | R31: =IFERROR(VLOOKUP(G31,'SOURCE COMPANY'!A:B, 2, FALSE), "") -> SISCO Research Labs | S31: =IFERROR(VLOOKUP(H31,'CUSTOMER NAME'!A:B, 2, FALSE), "") -> ALCHEMY SCIENTIFIC QUARTER
A32: Iraq | B32: 6 | C32: KGS | D32: SODIUM CMC | E32: 6.44 | F32: USD | G32: SISCO LABS | H32: ALCHEMY SCIENTIFIC QUARTER | I32: October | J32: =IF(F32="USD", E32, E32 * IFERROR(VLOOKUP(F32, EXCHANGE_RATE!A:B, 2, FALSE), "Currency not found")) -> 6.44 | K32: =ROUNDUP(J32,2) -> 6.44 | L32: =IF(C32="MTS", B32, B32 * IFERROR(VLOOKUP(C32, 'QTY_CONVERSIONS '!A:B, 2, FALSE), "Units not found")) -> 0.006 | M32: =B32*K32 -> 38.64 | N32: =IFERROR(VLOOKUP(D32, Product_Category!A:B, 2, FALSE), "Uncategorized") -> CMC | O32: =K32*1000 -> 6440 | P32: =L32*O32 -> 38.64 | Q32: 2023 | R32: =IFERROR(VLOOKUP(G32,'SOURCE COMPANY'!A:B, 2, FALSE), "") -> SISCO Research Labs | S32: =IFERROR(VLOOKUP(H32,'CUSTOMER NAME'!A:B, 2, FALSE), "") -> ALCHEMY SCIENTIFIC QUARTER
A33: Iraq | B33: 12 | C33: KGS | D33: MCC PURE TLC 98% | E33: 1.44 | F33: USD | G33: SISCO LABS | H33: ALCHEMY SCIENTIFIC QUARTER | I33: October | J33: =IF(F33="USD", E33, E33 * IFERROR(VLOOKUP(F33, EXCHANGE_RATE!A:B, 2, FALSE), "Currency not found")) -> 1.44 | K33: =ROUNDUP(J33,2) -> 1.44 | L33: =IF(C33="MTS", B33, B33 * IFERROR(VLOOKUP(C33, 'QTY_CONVERSIONS '!A:B, 2, FALSE), "Units not found")) -> 0.012 | M33: =B33*K33 -> 17.28 | N33: =IFERROR(VLOOKUP(D33, Product_Category!A:B, 2, FALSE), "Uncategorized") -> MCC | O33: =K33*1000 -> 1440 | P33: =L33*O33 -> 17.28 | Q33: 2023 | R33: =IFERROR(VLOOKUP(G33,'SOURCE COMPANY'!A:B, 2, FALSE), "") -> SISCO Research Labs | S33: =IFERROR(VLOOKUP(H33,'CUSTOMER NAME'!A:B, 2, FALSE), "") -> ALCHEMY SCIENTIFIC QUARTER
A34: Nicaragua | B34: 0.5 | C34: KGS | D34: SODIUM CMC | E34: 2 | F34: USD | G34: GEMINI EXPORTS | H34: ALCOBENDAS-MADRID VAT | I34: November | J34: =IF(F34="USD", E34, E34 * IFERROR(VLOOKUP(F34, EXCHANGE_RATE!A:B, 2, FALSE), "Currency not found")) -> 2 | K34: =ROUNDUP(J34,2) -> 2 | L34: =IF(C34="MTS", B34, B34 * IFERROR(VLOOKUP(C34, 'QTY_CONVERSIONS '!A:B, 2, FALSE), "Units not found")) -> 0.0005 | M34: =B34*K34 -> 1 | N34: =IFERROR(VLOOKUP(D34, Product_Category!A:B, 2, FALSE), "Uncategorized") -> CMC | O34: =K34*1000 -> 2000 | P34: =L34*O34 -> 1 | Q34: 2023 | R34: =IFERROR(VLOOKUP(G34,'SOURCE COMPANY'!A:B, 2, FALSE), "") -> GEMINI EXPORTS | S34: =IFERROR(VLOOKUP(H34,'CUSTOMER NAME'!A:B, 2, FALSE), "") -> ALCOBENDAS-MADRID VAT
A35: Nicaragua | B35: 700 | C35: KGS | D35: SODIUM CMC | E35: 6 | F35: USD | G35: GEMINI EXPORTS | H35: ALCOBENDAS-MADRID VAT | I35: November | J35: =IF(F35="USD", E35, E35 * IFERROR(VLOOKUP(F35, EXCHANGE_RATE!A:B, 2, FALSE), "Currency not found")) -> 6 | K35: =ROUNDUP(J35,2) -> 6 | L35: =IF(C35="MTS", B35, B35 * IFERROR(VLOOKUP(C35, 'QTY_CONVERSIONS '!A:B, 2, FALSE), "Units not found")) -> 0.7 | M35: =B35*K35 -> 4200 | N35: =IFERROR(VLOOKUP(D35, Product_Category!A:B, 2, FALSE), "Uncategorized") -> CMC | O35: =K35*1000 -> 6000 | P35: =L35*O35 -> 4200 | Q35: 2023 | R35: =IFERROR(VLOOKUP(G35,'SOURCE COMPANY'!A:B, 2, FALSE), "") -> GEMINI EXPORTS | S35: =IFERROR(VLOOKUP(H35,'CUSTOMER NAME'!A:B, 2, FALSE), "") -> ALCOBENDAS-MADRID VAT
A36: Mexico | B36: 50 | C36: KGS | D36: MICCEL-102 | E36: 16 | F36: USD | G36: ANKIT PULPS | H36: ALFAMEX INDUSTRIAL | I36: December | J36: =IF(F36="USD", E36, E36 * IFERROR(VLOOKUP(F36, EXCHANGE_RATE!A:B, 2, FALSE), "Currency not found")) -> 16 | K36: =ROUNDUP(J36,2) -> 16 | L36: =IF(C36="MTS", B36, B36 * IFERROR(VLOOKUP(C36, 'QTY_CONVERSIONS '!A:B, 2, FALSE), "Units not found")) -> 0.05 | M36: =B36*K36 -> 800 | N36: =IFERROR(VLOOKUP(D36, Product_Category!A:B, 2, FALSE), "Uncategorized") -> MCC | O36: =K36*1000 -> 16000 | P36: =L36*O36 -> 800 | Q36: 2023 | R36: =IFERROR(VLOOKUP(G36,'SOURCE COMPANY'!A:B, 2, FALSE), "") -> Ankit Pulps & Boards | S36: =IFERROR(VLOOKUP(H36,'CUSTOMER NAME'!A:B, 2, FALSE), "") -> ALFAMEX INDUSTRIAL
A37: Mexico | B37: 18000 | C37: KGS | D37: MCC PH-102 | E37: 2.75 | F37: USD | G37: MURLI KRISHNA EXPORTS | H37: ALI FARMA | I37: September | J37: =IF(F37="USD", E37, E37 * IFERROR(VLOOKUP(F37, EXCHANGE_RATE!A:B, 2, FALSE), "Currency not found")) -> 2.75 | K37: =ROUNDUP(J37,2) -> 2.75 | L37: =IF(C37="MTS", B37, B37 * IFERROR(VLOOKUP(C37, 'QTY_CONVERSIONS '!A:B, 2, FALSE), "Units not found")) -> 18 | M37: =B37*K37 -> 49500 | N37: =IFERROR(VLOOKUP(D37, Product_Category!A:B, 2, FALSE), "Uncategorized") -> MCC | O37: =K37*1000 -> 2750 | P37: =L37*O37 -> 49500 | Q37: 2023 | R37: =IFERROR(VLOOKUP(G37,'SOURCE COMPANY'!A:B, 2, FALSE), "") -> MURLI KRISHNA EXPORTS | S37: =IFERROR(VLOOKUP(H37,'CUSTOMER NAME'!A:B, 2, FALSE), "") -> ALI FARMA
A38: Myanmar | B38: 375 | C38: KGS | D38: MG STEARATE PH.EUR | E38: 2.57 | F38: USD | G38: CADILA HEALTHCARE | H38: ALIDAC HEALTHCARE | I38: =I37 -> September | J38: =IF(F38="USD", E38, E38 * IFERROR(VLOOKUP(F38, EXCHANGE_RATE!A:B, 2, FALSE), "Currency not found")) -> 2.57 | K38: =ROUNDUP(J38,2) -> 2.57 | L38: =IF(C38="MTS", B38, B38 * IFERROR(VLOOKUP(C38, 'QTY_CONVERSIONS '!A:B, 2, FALSE), "Units not found")) -> 0.375 | M38: =B38*K38 -> 963.75 | N38: =IFERROR(VLOOKUP(D38, Product_Category!A:B, 2, FALSE), "Uncategorized") -> MAGNESIUM STEARATE | O38: =K38*1000 -> 2570 | P38: =L38*O38 -> 963.75 | Q38: 2023 | R38: =IFERROR(VLOOKUP(G38,'SOURCE COMPANY'!A:B, 2, FALSE), "") -> CADILA HEALTHCARE | S38: =IFERROR(VLOOKUP(H38,'CUSTOMER NAME'!A:B, 2, FALSE), "") -> ALIDAC HEALTHCARE
A39: Myanmar | B39: 150 | C39: KGS | D39: SODIUM CCM | E39: 10.85 | F39: USD | G39: CADILA HEALTHCARE | H39: ALIDAC HEALTHCARE | I39: October | J39: =IF(F39="USD", E39, E39 * IFERROR(VLOOKUP(F39, EXCHANGE_RATE!A:B, 2, FALSE), "Currency not found")) -> 10.85 | K39: =ROUNDUP(J39,2) -> 10.85 | L39: =IF(C39="MTS", B39, B39 * IFERROR(VLOOKUP(C39, 'QTY_CONVERSIONS '!A:B, 2, FALSE), "Units not found")) -> 0.15 | M39: =B39*K39 -> 1627.5 | N39: =IFERROR(VLOOKUP(D39, Product_Category!A:B, 2, FALSE), "Uncategorized") -> CROSCARMELLOSE SODIUM | O39: =K39*1000 -> 10850 | P39: =L39*O39 -> 1627.5 | Q39: 2023 | R39: =IFERROR(VLOOKUP(G39,'SOURCE COMPANY'!A:B, 2, FALSE), "") -> CADILA HEALTHCARE | S39: =IFERROR(VLOOKUP(H39,'CUSTOMER NAME'!A:B, 2, FALSE), "") -> ALIDAC HEALTHCARE
A40: Myanmar | B40: 40 | C40: KGS | D40: MCC | E40: 5.43 | F40: USD | G40: CADILA HEALTHCARE | H40: ALIDAC HEALTHCARE | I40: October | J40: =IF(F40="USD", E40, E40 * IFERROR(VLOOKUP(F40, EXCHANGE_RATE!A:B, 2, FALSE), "Currency not found")) -> 5.43 | K40: =ROUNDUP(J40,2) -> 5.43 | L40: =IF(C40="MTS", B40, B40 * IFERROR(VLOOKUP(C40, 'QTY_CONVERSIONS '!A:B, 2, FALSE), "Units not found")) -> 0.04 | M40: =B40*K40 -> 217.2 | N40: =IFERROR(VLOOKUP(D40, Product_Category!A:B, 2, FALSE), "Uncategorized") -> MCC | O40: =K40*1000 -> 5430 | P40: =L40*O40 -> 217.2 | Q40: 2023 | R40: =IFERROR(VLOOKUP(G40,'SOURCE COMPANY'!A:B, 2, FALSE), "") -> CADILA HEALTHCARE | S40: =IFERROR(VLOOKUP(H40,'CUSTOMER NAME'!A:B, 2, FALSE), "") -> ALIDAC HEALTHCARE
...

Sheet Product_Category
A1: Product Name | B1: Category
A2: MCCP ACECEL 102 (90M) USP | B2: MCC
A3: MICROCEL MCC-101 | B3: MCC
A4: MICROCEL MCC-102 | B4: MCC
A5: MICROCEL MCC-200 | B5: MCC
A6: SODIUM CMC | B6: CMC
A7: CELLULOSE ETHER-SODIUM CMC | B7: CMC
A8: GRINDSTED CELLULOSE GUM SODIUM CMC | B8: CMC
A9: SODIUM CMC USP | B9: CMC
A10: CMC | B10: CMC
A11: PROSOLV SMCC 50 | B11: MCC
A12: FINNFIX 10 - SODIUM CMC | B12: CMC
... A1075: MICROCEL MC-101 MCC | B1075: MCC
A1076: MICROCEL MC-101 SCOPE MCC | B1076: =B1075 -> MCC
A1077: MICROCEL MC-102 SCOPE MCC | B1077: =B1076 -> MCC
A1078: MCC MICROCEL 112 | B1078: =B1077 -> MCC
A1079: PROSOLV SMCC 51 | B1079: =B1078 -> MCC
A1080: PROSOLV SMCC 52 | B1080: =B1079 -> MCC
